{"uuid": "622b230f-5dd2-4bff-b07d-9e1e5d537d40", "children": ["70a243a4-3b3e-44c5-8d06-ed7e67aeca75"], "befores": [{"name": "driver", "status": "broken", "statusDetails": {"message": "urllib3.exceptions.MaxRetryError: HTTPConnectionPool(host='127.0.0.1', port=52900): Max retries exceeded with url: /session/1b505b0d8e503cb9c1e0fbf77d939035/window/maximize (Caused by NewConnectionError('<urllib3.connection.HTTPConnection object at 0x000001C10715C1C8>: Failed to establish a new connection: [WinError 10061] 由于目标计算机积极拒绝，无法连接。'))\n", "trace": "  File \"c:\\users\\administrator\\pycharmprojects\\cspytest\\venv\\lib\\site-packages\\pluggy\\callers.py\", line 187, in _multicall\n    res = hook_impl.function(*args)\n  File \"c:\\users\\administrator\\pycharmprojects\\cspytest\\venv\\lib\\site-packages\\_pytest\\fixtures.py\", line 1117, in pytest_fixture_setup\n    result = call_fixture_func(fixturefunc, request, kwargs)\n  File \"c:\\users\\administrator\\pycharmprojects\\cspytest\\venv\\lib\\site-packages\\_pytest\\fixtures.py\", line 915, in call_fixture_func\n    fixture_result = next(generator)\n  File \"C:\\Users\\Administrator\\PycharmProjects\\cspytest\\conftest.py\", line 52, in driver\n    _driver.maximize_window()  # 最大化\n  File \"c:\\users\\administrator\\pycharmprojects\\cspytest\\venv\\lib\\site-packages\\selenium\\webdriver\\remote\\webdriver.py\", line 737, in maximize_window\n    self.execute(command, params)\n  File \"c:\\users\\administrator\\pycharmprojects\\cspytest\\venv\\lib\\site-packages\\selenium\\webdriver\\remote\\webdriver.py\", line 319, in execute\n    response = self.command_executor.execute(driver_command, params)\n  File \"c:\\users\\administrator\\pycharmprojects\\cspytest\\venv\\lib\\site-packages\\selenium\\webdriver\\remote\\remote_connection.py\", line 374, in execute\n    return self._request(command_info[0], url, body=data)\n  File \"c:\\users\\administrator\\pycharmprojects\\cspytest\\venv\\lib\\site-packages\\selenium\\webdriver\\remote\\remote_connection.py\", line 397, in _request\n    resp = self._conn.request(method, url, body=body, headers=headers)\n  File \"c:\\users\\administrator\\pycharmprojects\\cspytest\\venv\\lib\\site-packages\\urllib3\\request.py\", line 80, in request\n    method, url, fields=fields, headers=headers, **urlopen_kw\n  File \"c:\\users\\administrator\\pycharmprojects\\cspytest\\venv\\lib\\site-packages\\urllib3\\request.py\", line 171, in request_encode_body\n    return self.urlopen(method, url, **extra_kw)\n  File \"c:\\users\\administrator\\pycharmprojects\\cspytest\\venv\\lib\\site-packages\\urllib3\\poolmanager.py\", line 336, in urlopen\n    response = conn.urlopen(method, u.request_uri, **kw)\n  File \"c:\\users\\administrator\\pycharmprojects\\cspytest\\venv\\lib\\site-packages\\urllib3\\connectionpool.py\", line 767, in urlopen\n    **response_kw\n  File \"c:\\users\\administrator\\pycharmprojects\\cspytest\\venv\\lib\\site-packages\\urllib3\\connectionpool.py\", line 767, in urlopen\n    **response_kw\n  File \"c:\\users\\administrator\\pycharmprojects\\cspytest\\venv\\lib\\site-packages\\urllib3\\connectionpool.py\", line 767, in urlopen\n    **response_kw\n  File \"c:\\users\\administrator\\pycharmprojects\\cspytest\\venv\\lib\\site-packages\\urllib3\\connectionpool.py\", line 727, in urlopen\n    method, url, error=e, _pool=self, _stacktrace=sys.exc_info()[2]\n  File \"c:\\users\\administrator\\pycharmprojects\\cspytest\\venv\\lib\\site-packages\\urllib3\\util\\retry.py\", line 439, in increment\n    raise MaxRetryError(_pool, url, error or ResponseError(cause))\n"}, "start": 1604900008801, "stop": 1604900012815}], "start": 1604900008801, "stop": 1604900013257}