{"uuid": "a52f8093-fc20-4692-a58b-8aa58767f8da", "children": ["480dfc10-53bb-4bbd-b3ee-7ba3a4e4f515", "6a8e66f3-f1e2-4685-b402-ae110d7fd694", "b3dc1a8d-884e-44c7-8fa1-01ccf5d88f59", "b7b21bfe-b914-42fe-8c9e-ca86efc34ca7", "1da7d740-90bb-4e90-89ee-ce77cb280a02", "f05bb6cb-9b6e-4c0e-a90b-3fb436e4af8e", "704c6b4e-6d93-49ce-b065-3ec223615e5d", "28c817b4-99e8-4258-a437-3034d0d1ba15", "874def95-0aa7-4971-9497-17503ad133f8", "f87300e8-e4e8-41c1-a9b2-37beb1e500dc", "3a3e77b2-f043-42c7-8553-fd4d9f8c1ed4", "6d981ebf-67b0-437e-b6f3-2d83cce89305", "c0f4eadb-5332-467a-9903-852e10d26deb", "9b6f9d5b-f9c0-4c6e-b928-088cac511f27", "ad137c7d-c7f4-4710-84d4-c21c06a415e3", "a87ca194-b463-42af-9899-5d8dd95d6a13", "2bdb9b6d-2dcb-4429-bb87-d95169b2f115", "4f8ee866-3c18-4d15-bb6b-e00b56c74d05", "00b288c2-6582-4a02-bf86-28bb00ee6982", "9208c7b8-b616-4681-ada2-daaf7e16c354", "29e9b91b-7b0c-47a5-aaaa-8ed1b395d7fa", "861a39e0-870a-4ac5-923e-e600a2d045ff", "340c4fe2-3e6b-4cc8-a165-3e82bdeb1861", "b303fb54-3a57-487b-80c5-46f7cf6c5e9d", "00ad52a6-8ecf-4dc1-8244-93f74a96d29c", "89d98409-d71c-4335-801a-8e5d9ddeb8a3", "aab517bb-64ef-4260-9141-0b2e2f3ac7e6", "825ccf58-e30e-4e21-ad60-dde964856a07"], "befores": [{"name": "login", "status": "broken", "statusDetails": {"message": "IndexError: list index out of range\n", "trace": "  File \"c:\\users\\administrator\\pycharmprojects\\cspytest\\venv\\lib\\site-packages\\pluggy\\callers.py\", line 187, in _multicall\n    res = hook_impl.function(*args)\n  File \"c:\\users\\administrator\\pycharmprojects\\cspytest\\venv\\lib\\site-packages\\_pytest\\fixtures.py\", line 1117, in pytest_fixture_setup\n    result = call_fixture_func(fixturefunc, request, kwargs)\n  File \"c:\\users\\administrator\\pycharmprojects\\cspytest\\venv\\lib\\site-packages\\_pytest\\fixtures.py\", line 924, in call_fixture_func\n    fixture_result = fixturefunc(**kwargs)\n  File \"C:\\Users\\Administrator\\PycharmProjects\\cspytest\\conftest.py\", line 79, in login\n    web.login(ini.username, ini.password, ini.verificationCode)\n  File \"c:\\users\\administrator\\pycharmprojects\\cspytest\\venv\\lib\\site-packages\\allure_commons\\_allure.py\", line 157, in impl\n    return func(*a, **kw)\n  File \"C:\\Users\\Administrator\\PycharmProjects\\cspytest\\pageobject\\loginpage.py\", line 28, in login\n    self.send_keys(loc.input_verificationCode, verificationCode, doc=doc)  # 输入验证码，不用就注掉\n  File \"C:\\Users\\Administrator\\PycharmProjects\\cspytest\\pageobject\\basepage.py\", line 220, in send_keys\n    elements[index].click()  # 点击\n"}, "steps": [{"name": "登录", "status": "broken", "statusDetails": {"message": "IndexError: list index out of range\n", "trace": "  File \"c:\\users\\administrator\\pycharmprojects\\cspytest\\venv\\lib\\site-packages\\allure_commons\\_allure.py\", line 157, in impl\n    return func(*a, **kw)\n  File \"C:\\Users\\Administrator\\PycharmProjects\\cspytest\\pageobject\\loginpage.py\", line 28, in login\n    self.send_keys(loc.input_verificationCode, verificationCode, doc=doc)  # 输入验证码，不用就注掉\n  File \"C:\\Users\\Administrator\\PycharmProjects\\cspytest\\pageobject\\basepage.py\", line 220, in send_keys\n    elements[index].click()  # 点击\n"}, "parameters": [{"name": "username", "value": "'hnadmin'"}, {"name": "password", "value": "'1qaz!QAZ'"}, {"name": "verificationCode", "value": "'9527'"}], "start": 1604899912321, "stop": 1604899968253}], "start": 1604899912319, "stop": 1604899968254}, {"name": "login", "status": "broken", "statusDetails": {"message": "IndexError: list index out of range\n", "trace": "  File \"c:\\users\\administrator\\pycharmprojects\\cspytest\\venv\\lib\\site-packages\\pluggy\\callers.py\", line 187, in _multicall\n    res = hook_impl.function(*args)\n  File \"c:\\users\\administrator\\pycharmprojects\\cspytest\\venv\\lib\\site-packages\\_pytest\\fixtures.py\", line 1117, in pytest_fixture_setup\n    result = call_fixture_func(fixturefunc, request, kwargs)\n  File \"c:\\users\\administrator\\pycharmprojects\\cspytest\\venv\\lib\\site-packages\\_pytest\\fixtures.py\", line 924, in call_fixture_func\n    fixture_result = fixturefunc(**kwargs)\n  File \"C:\\Users\\Administrator\\PycharmProjects\\cspytest\\conftest.py\", line 79, in login\n    web.login(ini.username, ini.password, ini.verificationCode)\n  File \"c:\\users\\administrator\\pycharmprojects\\cspytest\\venv\\lib\\site-packages\\allure_commons\\_allure.py\", line 157, in impl\n    return func(*a, **kw)\n  File \"C:\\Users\\Administrator\\PycharmProjects\\cspytest\\pageobject\\loginpage.py\", line 28, in login\n    self.send_keys(loc.input_verificationCode, verificationCode, doc=doc)  # 输入验证码，不用就注掉\n  File \"C:\\Users\\Administrator\\PycharmProjects\\cspytest\\pageobject\\basepage.py\", line 220, in send_keys\n    elements[index].click()  # 点击\n"}, "steps": [{"name": "登录", "status": "broken", "statusDetails": {"message": "IndexError: list index out of range\n", "trace": "  File \"c:\\users\\administrator\\pycharmprojects\\cspytest\\venv\\lib\\site-packages\\allure_commons\\_allure.py\", line 157, in impl\n    return func(*a, **kw)\n  File \"C:\\Users\\Administrator\\PycharmProjects\\cspytest\\pageobject\\loginpage.py\", line 28, in login\n    self.send_keys(loc.input_verificationCode, verificationCode, doc=doc)  # 输入验证码，不用就注掉\n  File \"C:\\Users\\Administrator\\PycharmProjects\\cspytest\\pageobject\\basepage.py\", line 220, in send_keys\n    elements[index].click()  # 点击\n"}, "parameters": [{"name": "username", "value": "'hnadmin'"}, {"name": "password", "value": "'1qaz!QAZ'"}, {"name": "verificationCode", "value": "'9527'"}], "start": 1604899968362, "stop": 1604900001608}], "start": 1604899968358, "stop": 1604900001608}, {"name": "login", "status": "broken", "statusDetails": {"message": "IndexError: list index out of range\n", "trace": "  File \"c:\\users\\administrator\\pycharmprojects\\cspytest\\venv\\lib\\site-packages\\pluggy\\callers.py\", line 187, in _multicall\n    res = hook_impl.function(*args)\n  File \"c:\\users\\administrator\\pycharmprojects\\cspytest\\venv\\lib\\site-packages\\_pytest\\fixtures.py\", line 1117, in pytest_fixture_setup\n    result = call_fixture_func(fixturefunc, request, kwargs)\n  File \"c:\\users\\administrator\\pycharmprojects\\cspytest\\venv\\lib\\site-packages\\_pytest\\fixtures.py\", line 924, in call_fixture_func\n    fixture_result = fixturefunc(**kwargs)\n  File \"C:\\Users\\Administrator\\PycharmProjects\\cspytest\\conftest.py\", line 79, in login\n    web.login(ini.username, ini.password, ini.verificationCode)\n  File \"c:\\users\\administrator\\pycharmprojects\\cspytest\\venv\\lib\\site-packages\\allure_commons\\_allure.py\", line 157, in impl\n    return func(*a, **kw)\n  File \"C:\\Users\\Administrator\\PycharmProjects\\cspytest\\pageobject\\loginpage.py\", line 28, in login\n    self.send_keys(loc.input_verificationCode, verificationCode, doc=doc)  # 输入验证码，不用就注掉\n  File \"C:\\Users\\Administrator\\PycharmProjects\\cspytest\\pageobject\\basepage.py\", line 220, in send_keys\n    elements[index].click()  # 点击\n"}, "steps": [{"name": "登录", "status": "broken", "statusDetails": {"message": "IndexError: list index out of range\n", "trace": "  File \"c:\\users\\administrator\\pycharmprojects\\cspytest\\venv\\lib\\site-packages\\allure_commons\\_allure.py\", line 157, in impl\n    return func(*a, **kw)\n  File \"C:\\Users\\Administrator\\PycharmProjects\\cspytest\\pageobject\\loginpage.py\", line 28, in login\n    self.send_keys(loc.input_verificationCode, verificationCode, doc=doc)  # 输入验证码，不用就注掉\n  File \"C:\\Users\\Administrator\\PycharmProjects\\cspytest\\pageobject\\basepage.py\", line 220, in send_keys\n    elements[index].click()  # 点击\n"}, "parameters": [{"name": "username", "value": "'hnadmin'"}, {"name": "password", "value": "'1qaz!QAZ'"}, {"name": "verificationCode", "value": "'9527'"}], "start": 1604900001694, "stop": 1604900005407}], "start": 1604900001690, "stop": 1604900005407}, {"name": "login", "status": "broken", "statusDetails": {"message": "selenium.common.exceptions.NoSuchWindowException: Message: no such window: target window already closed\nfrom unknown error: web view not found\n  (Session info: chrome=86.0.4240.183)\n\n", "trace": "  File \"c:\\users\\administrator\\pycharmprojects\\cspytest\\venv\\lib\\site-packages\\pluggy\\callers.py\", line 187, in _multicall\n    res = hook_impl.function(*args)\n  File \"c:\\users\\administrator\\pycharmprojects\\cspytest\\venv\\lib\\site-packages\\_pytest\\fixtures.py\", line 1117, in pytest_fixture_setup\n    result = call_fixture_func(fixturefunc, request, kwargs)\n  File \"c:\\users\\administrator\\pycharmprojects\\cspytest\\venv\\lib\\site-packages\\_pytest\\fixtures.py\", line 924, in call_fixture_func\n    fixture_result = fixturefunc(**kwargs)\n  File \"C:\\Users\\Administrator\\PycharmProjects\\cspytest\\conftest.py\", line 79, in login\n    web.login(ini.username, ini.password, ini.verificationCode)\n  File \"c:\\users\\administrator\\pycharmprojects\\cspytest\\venv\\lib\\site-packages\\allure_commons\\_allure.py\", line 157, in impl\n    return func(*a, **kw)\n  File \"C:\\Users\\Administrator\\PycharmProjects\\cspytest\\pageobject\\loginpage.py\", line 22, in login\n    self.driver.get(ini.url)  # 调用浏览器打开测试地址\n  File \"c:\\users\\administrator\\pycharmprojects\\cspytest\\venv\\lib\\site-packages\\selenium\\webdriver\\remote\\webdriver.py\", line 333, in get\n    self.execute(Command.GET, {'url': url})\n  File \"c:\\users\\administrator\\pycharmprojects\\cspytest\\venv\\lib\\site-packages\\selenium\\webdriver\\remote\\webdriver.py\", line 321, in execute\n    self.error_handler.check_response(response)\n  File \"c:\\users\\administrator\\pycharmprojects\\cspytest\\venv\\lib\\site-packages\\selenium\\webdriver\\remote\\errorhandler.py\", line 242, in check_response\n    raise exception_class(message, screen, stacktrace)\n"}, "steps": [{"name": "登录", "status": "broken", "statusDetails": {"message": "selenium.common.exceptions.NoSuchWindowException: Message: no such window: target window already closed\nfrom unknown error: web view not found\n  (Session info: chrome=86.0.4240.183)\n\n", "trace": "  File \"c:\\users\\administrator\\pycharmprojects\\cspytest\\venv\\lib\\site-packages\\allure_commons\\_allure.py\", line 157, in impl\n    return func(*a, **kw)\n  File \"C:\\Users\\Administrator\\PycharmProjects\\cspytest\\pageobject\\loginpage.py\", line 22, in login\n    self.driver.get(ini.url)  # 调用浏览器打开测试地址\n  File \"c:\\users\\administrator\\pycharmprojects\\cspytest\\venv\\lib\\site-packages\\selenium\\webdriver\\remote\\webdriver.py\", line 333, in get\n    self.execute(Command.GET, {'url': url})\n  File \"c:\\users\\administrator\\pycharmprojects\\cspytest\\venv\\lib\\site-packages\\selenium\\webdriver\\remote\\webdriver.py\", line 321, in execute\n    self.error_handler.check_response(response)\n  File \"c:\\users\\administrator\\pycharmprojects\\cspytest\\venv\\lib\\site-packages\\selenium\\webdriver\\remote\\errorhandler.py\", line 242, in check_response\n    raise exception_class(message, screen, stacktrace)\n"}, "parameters": [{"name": "username", "value": "'hnadmin'"}, {"name": "password", "value": "'1qaz!QAZ'"}, {"name": "verificationCode", "value": "'9527'"}], "start": 1604900005572, "stop": 1604900005576}], "start": 1604900005567, "stop": 1604900005577}, {"name": "login", "status": "broken", "statusDetails": {"message": "selenium.common.exceptions.NoSuchWindowException: Message: no such window: target window already closed\nfrom unknown error: web view not found\n  (Session info: chrome=86.0.4240.183)\n\n", "trace": "  File \"c:\\users\\administrator\\pycharmprojects\\cspytest\\venv\\lib\\site-packages\\pluggy\\callers.py\", line 187, in _multicall\n    res = hook_impl.function(*args)\n  File \"c:\\users\\administrator\\pycharmprojects\\cspytest\\venv\\lib\\site-packages\\_pytest\\fixtures.py\", line 1117, in pytest_fixture_setup\n    result = call_fixture_func(fixturefunc, request, kwargs)\n  File \"c:\\users\\administrator\\pycharmprojects\\cspytest\\venv\\lib\\site-packages\\_pytest\\fixtures.py\", line 924, in call_fixture_func\n    fixture_result = fixturefunc(**kwargs)\n  File \"C:\\Users\\Administrator\\PycharmProjects\\cspytest\\conftest.py\", line 79, in login\n    web.login(ini.username, ini.password, ini.verificationCode)\n  File \"c:\\users\\administrator\\pycharmprojects\\cspytest\\venv\\lib\\site-packages\\allure_commons\\_allure.py\", line 157, in impl\n    return func(*a, **kw)\n  File \"C:\\Users\\Administrator\\PycharmProjects\\cspytest\\pageobject\\loginpage.py\", line 22, in login\n    self.driver.get(ini.url)  # 调用浏览器打开测试地址\n  File \"c:\\users\\administrator\\pycharmprojects\\cspytest\\venv\\lib\\site-packages\\selenium\\webdriver\\remote\\webdriver.py\", line 333, in get\n    self.execute(Command.GET, {'url': url})\n  File \"c:\\users\\administrator\\pycharmprojects\\cspytest\\venv\\lib\\site-packages\\selenium\\webdriver\\remote\\webdriver.py\", line 321, in execute\n    self.error_handler.check_response(response)\n  File \"c:\\users\\administrator\\pycharmprojects\\cspytest\\venv\\lib\\site-packages\\selenium\\webdriver\\remote\\errorhandler.py\", line 242, in check_response\n    raise exception_class(message, screen, stacktrace)\n"}, "steps": [{"name": "登录", "status": "broken", "statusDetails": {"message": "selenium.common.exceptions.NoSuchWindowException: Message: no such window: target window already closed\nfrom unknown error: web view not found\n  (Session info: chrome=86.0.4240.183)\n\n", "trace": "  File \"c:\\users\\administrator\\pycharmprojects\\cspytest\\venv\\lib\\site-packages\\allure_commons\\_allure.py\", line 157, in impl\n    return func(*a, **kw)\n  File \"C:\\Users\\Administrator\\PycharmProjects\\cspytest\\pageobject\\loginpage.py\", line 22, in login\n    self.driver.get(ini.url)  # 调用浏览器打开测试地址\n  File \"c:\\users\\administrator\\pycharmprojects\\cspytest\\venv\\lib\\site-packages\\selenium\\webdriver\\remote\\webdriver.py\", line 333, in get\n    self.execute(Command.GET, {'url': url})\n  File \"c:\\users\\administrator\\pycharmprojects\\cspytest\\venv\\lib\\site-packages\\selenium\\webdriver\\remote\\webdriver.py\", line 321, in execute\n    self.error_handler.check_response(response)\n  File \"c:\\users\\administrator\\pycharmprojects\\cspytest\\venv\\lib\\site-packages\\selenium\\webdriver\\remote\\errorhandler.py\", line 242, in check_response\n    raise exception_class(message, screen, stacktrace)\n"}, "parameters": [{"name": "username", "value": "'hnadmin'"}, {"name": "password", "value": "'1qaz!QAZ'"}, {"name": "verificationCode", "value": "'9527'"}], "start": 1604900005723, "stop": 1604900005727}], "start": 1604900005719, "stop": 1604900005728}, {"name": "login", "status": "broken", "statusDetails": {"message": "selenium.common.exceptions.NoSuchWindowException: Message: no such window: target window already closed\nfrom unknown error: web view not found\n  (Session info: chrome=86.0.4240.183)\n\n", "trace": "  File \"c:\\users\\administrator\\pycharmprojects\\cspytest\\venv\\lib\\site-packages\\pluggy\\callers.py\", line 187, in _multicall\n    res = hook_impl.function(*args)\n  File \"c:\\users\\administrator\\pycharmprojects\\cspytest\\venv\\lib\\site-packages\\_pytest\\fixtures.py\", line 1117, in pytest_fixture_setup\n    result = call_fixture_func(fixturefunc, request, kwargs)\n  File \"c:\\users\\administrator\\pycharmprojects\\cspytest\\venv\\lib\\site-packages\\_pytest\\fixtures.py\", line 924, in call_fixture_func\n    fixture_result = fixturefunc(**kwargs)\n  File \"C:\\Users\\Administrator\\PycharmProjects\\cspytest\\conftest.py\", line 79, in login\n    web.login(ini.username, ini.password, ini.verificationCode)\n  File \"c:\\users\\administrator\\pycharmprojects\\cspytest\\venv\\lib\\site-packages\\allure_commons\\_allure.py\", line 157, in impl\n    return func(*a, **kw)\n  File \"C:\\Users\\Administrator\\PycharmProjects\\cspytest\\pageobject\\loginpage.py\", line 22, in login\n    self.driver.get(ini.url)  # 调用浏览器打开测试地址\n  File \"c:\\users\\administrator\\pycharmprojects\\cspytest\\venv\\lib\\site-packages\\selenium\\webdriver\\remote\\webdriver.py\", line 333, in get\n    self.execute(Command.GET, {'url': url})\n  File \"c:\\users\\administrator\\pycharmprojects\\cspytest\\venv\\lib\\site-packages\\selenium\\webdriver\\remote\\webdriver.py\", line 321, in execute\n    self.error_handler.check_response(response)\n  File \"c:\\users\\administrator\\pycharmprojects\\cspytest\\venv\\lib\\site-packages\\selenium\\webdriver\\remote\\errorhandler.py\", line 242, in check_response\n    raise exception_class(message, screen, stacktrace)\n"}, "steps": [{"name": "登录", "status": "broken", "statusDetails": {"message": "selenium.common.exceptions.NoSuchWindowException: Message: no such window: target window already closed\nfrom unknown error: web view not found\n  (Session info: chrome=86.0.4240.183)\n\n", "trace": "  File \"c:\\users\\administrator\\pycharmprojects\\cspytest\\venv\\lib\\site-packages\\allure_commons\\_allure.py\", line 157, in impl\n    return func(*a, **kw)\n  File \"C:\\Users\\Administrator\\PycharmProjects\\cspytest\\pageobject\\loginpage.py\", line 22, in login\n    self.driver.get(ini.url)  # 调用浏览器打开测试地址\n  File \"c:\\users\\administrator\\pycharmprojects\\cspytest\\venv\\lib\\site-packages\\selenium\\webdriver\\remote\\webdriver.py\", line 333, in get\n    self.execute(Command.GET, {'url': url})\n  File \"c:\\users\\administrator\\pycharmprojects\\cspytest\\venv\\lib\\site-packages\\selenium\\webdriver\\remote\\webdriver.py\", line 321, in execute\n    self.error_handler.check_response(response)\n  File \"c:\\users\\administrator\\pycharmprojects\\cspytest\\venv\\lib\\site-packages\\selenium\\webdriver\\remote\\errorhandler.py\", line 242, in check_response\n    raise exception_class(message, screen, stacktrace)\n"}, "parameters": [{"name": "username", "value": "'hnadmin'"}, {"name": "password", "value": "'1qaz!QAZ'"}, {"name": "verificationCode", "value": "'9527'"}], "start": 1604900005852, "stop": 1604900005855}], "start": 1604900005849, "stop": 1604900005855}, {"name": "login", "status": "broken", "statusDetails": {"message": "selenium.common.exceptions.NoSuchWindowException: Message: no such window: target window already closed\nfrom unknown error: web view not found\n  (Session info: chrome=86.0.4240.183)\n\n", "trace": "  File \"c:\\users\\administrator\\pycharmprojects\\cspytest\\venv\\lib\\site-packages\\pluggy\\callers.py\", line 187, in _multicall\n    res = hook_impl.function(*args)\n  File \"c:\\users\\administrator\\pycharmprojects\\cspytest\\venv\\lib\\site-packages\\_pytest\\fixtures.py\", line 1117, in pytest_fixture_setup\n    result = call_fixture_func(fixturefunc, request, kwargs)\n  File \"c:\\users\\administrator\\pycharmprojects\\cspytest\\venv\\lib\\site-packages\\_pytest\\fixtures.py\", line 924, in call_fixture_func\n    fixture_result = fixturefunc(**kwargs)\n  File \"C:\\Users\\Administrator\\PycharmProjects\\cspytest\\conftest.py\", line 79, in login\n    web.login(ini.username, ini.password, ini.verificationCode)\n  File \"c:\\users\\administrator\\pycharmprojects\\cspytest\\venv\\lib\\site-packages\\allure_commons\\_allure.py\", line 157, in impl\n    return func(*a, **kw)\n  File \"C:\\Users\\Administrator\\PycharmProjects\\cspytest\\pageobject\\loginpage.py\", line 22, in login\n    self.driver.get(ini.url)  # 调用浏览器打开测试地址\n  File \"c:\\users\\administrator\\pycharmprojects\\cspytest\\venv\\lib\\site-packages\\selenium\\webdriver\\remote\\webdriver.py\", line 333, in get\n    self.execute(Command.GET, {'url': url})\n  File \"c:\\users\\administrator\\pycharmprojects\\cspytest\\venv\\lib\\site-packages\\selenium\\webdriver\\remote\\webdriver.py\", line 321, in execute\n    self.error_handler.check_response(response)\n  File \"c:\\users\\administrator\\pycharmprojects\\cspytest\\venv\\lib\\site-packages\\selenium\\webdriver\\remote\\errorhandler.py\", line 242, in check_response\n    raise exception_class(message, screen, stacktrace)\n"}, "steps": [{"name": "登录", "status": "broken", "statusDetails": {"message": "selenium.common.exceptions.NoSuchWindowException: Message: no such window: target window already closed\nfrom unknown error: web view not found\n  (Session info: chrome=86.0.4240.183)\n\n", "trace": "  File \"c:\\users\\administrator\\pycharmprojects\\cspytest\\venv\\lib\\site-packages\\allure_commons\\_allure.py\", line 157, in impl\n    return func(*a, **kw)\n  File \"C:\\Users\\Administrator\\PycharmProjects\\cspytest\\pageobject\\loginpage.py\", line 22, in login\n    self.driver.get(ini.url)  # 调用浏览器打开测试地址\n  File \"c:\\users\\administrator\\pycharmprojects\\cspytest\\venv\\lib\\site-packages\\selenium\\webdriver\\remote\\webdriver.py\", line 333, in get\n    self.execute(Command.GET, {'url': url})\n  File \"c:\\users\\administrator\\pycharmprojects\\cspytest\\venv\\lib\\site-packages\\selenium\\webdriver\\remote\\webdriver.py\", line 321, in execute\n    self.error_handler.check_response(response)\n  File \"c:\\users\\administrator\\pycharmprojects\\cspytest\\venv\\lib\\site-packages\\selenium\\webdriver\\remote\\errorhandler.py\", line 242, in check_response\n    raise exception_class(message, screen, stacktrace)\n"}, "parameters": [{"name": "username", "value": "'hnadmin'"}, {"name": "password", "value": "'1qaz!QAZ'"}, {"name": "verificationCode", "value": "'9527'"}], "start": 1604900005955, "stop": 1604900005958}], "start": 1604900005952, "stop": 1604900005959}, {"name": "login", "status": "broken", "statusDetails": {"message": "selenium.common.exceptions.NoSuchWindowException: Message: no such window: target window already closed\nfrom unknown error: web view not found\n  (Session info: chrome=86.0.4240.183)\n\n", "trace": "  File \"c:\\users\\administrator\\pycharmprojects\\cspytest\\venv\\lib\\site-packages\\pluggy\\callers.py\", line 187, in _multicall\n    res = hook_impl.function(*args)\n  File \"c:\\users\\administrator\\pycharmprojects\\cspytest\\venv\\lib\\site-packages\\_pytest\\fixtures.py\", line 1117, in pytest_fixture_setup\n    result = call_fixture_func(fixturefunc, request, kwargs)\n  File \"c:\\users\\administrator\\pycharmprojects\\cspytest\\venv\\lib\\site-packages\\_pytest\\fixtures.py\", line 924, in call_fixture_func\n    fixture_result = fixturefunc(**kwargs)\n  File \"C:\\Users\\Administrator\\PycharmProjects\\cspytest\\conftest.py\", line 79, in login\n    web.login(ini.username, ini.password, ini.verificationCode)\n  File \"c:\\users\\administrator\\pycharmprojects\\cspytest\\venv\\lib\\site-packages\\allure_commons\\_allure.py\", line 157, in impl\n    return func(*a, **kw)\n  File \"C:\\Users\\Administrator\\PycharmProjects\\cspytest\\pageobject\\loginpage.py\", line 22, in login\n    self.driver.get(ini.url)  # 调用浏览器打开测试地址\n  File \"c:\\users\\administrator\\pycharmprojects\\cspytest\\venv\\lib\\site-packages\\selenium\\webdriver\\remote\\webdriver.py\", line 333, in get\n    self.execute(Command.GET, {'url': url})\n  File \"c:\\users\\administrator\\pycharmprojects\\cspytest\\venv\\lib\\site-packages\\selenium\\webdriver\\remote\\webdriver.py\", line 321, in execute\n    self.error_handler.check_response(response)\n  File \"c:\\users\\administrator\\pycharmprojects\\cspytest\\venv\\lib\\site-packages\\selenium\\webdriver\\remote\\errorhandler.py\", line 242, in check_response\n    raise exception_class(message, screen, stacktrace)\n"}, "steps": [{"name": "登录", "status": "broken", "statusDetails": {"message": "selenium.common.exceptions.NoSuchWindowException: Message: no such window: target window already closed\nfrom unknown error: web view not found\n  (Session info: chrome=86.0.4240.183)\n\n", "trace": "  File \"c:\\users\\administrator\\pycharmprojects\\cspytest\\venv\\lib\\site-packages\\allure_commons\\_allure.py\", line 157, in impl\n    return func(*a, **kw)\n  File \"C:\\Users\\Administrator\\PycharmProjects\\cspytest\\pageobject\\loginpage.py\", line 22, in login\n    self.driver.get(ini.url)  # 调用浏览器打开测试地址\n  File \"c:\\users\\administrator\\pycharmprojects\\cspytest\\venv\\lib\\site-packages\\selenium\\webdriver\\remote\\webdriver.py\", line 333, in get\n    self.execute(Command.GET, {'url': url})\n  File \"c:\\users\\administrator\\pycharmprojects\\cspytest\\venv\\lib\\site-packages\\selenium\\webdriver\\remote\\webdriver.py\", line 321, in execute\n    self.error_handler.check_response(response)\n  File \"c:\\users\\administrator\\pycharmprojects\\cspytest\\venv\\lib\\site-packages\\selenium\\webdriver\\remote\\errorhandler.py\", line 242, in check_response\n    raise exception_class(message, screen, stacktrace)\n"}, "parameters": [{"name": "username", "value": "'hnadmin'"}, {"name": "password", "value": "'1qaz!QAZ'"}, {"name": "verificationCode", "value": "'9527'"}], "start": 1604900006054, "stop": 1604900006057}], "start": 1604900006052, "stop": 1604900006058}, {"name": "login", "status": "broken", "statusDetails": {"message": "selenium.common.exceptions.NoSuchWindowException: Message: no such window: target window already closed\nfrom unknown error: web view not found\n  (Session info: chrome=86.0.4240.183)\n\n", "trace": "  File \"c:\\users\\administrator\\pycharmprojects\\cspytest\\venv\\lib\\site-packages\\pluggy\\callers.py\", line 187, in _multicall\n    res = hook_impl.function(*args)\n  File \"c:\\users\\administrator\\pycharmprojects\\cspytest\\venv\\lib\\site-packages\\_pytest\\fixtures.py\", line 1117, in pytest_fixture_setup\n    result = call_fixture_func(fixturefunc, request, kwargs)\n  File \"c:\\users\\administrator\\pycharmprojects\\cspytest\\venv\\lib\\site-packages\\_pytest\\fixtures.py\", line 924, in call_fixture_func\n    fixture_result = fixturefunc(**kwargs)\n  File \"C:\\Users\\Administrator\\PycharmProjects\\cspytest\\conftest.py\", line 79, in login\n    web.login(ini.username, ini.password, ini.verificationCode)\n  File \"c:\\users\\administrator\\pycharmprojects\\cspytest\\venv\\lib\\site-packages\\allure_commons\\_allure.py\", line 157, in impl\n    return func(*a, **kw)\n  File \"C:\\Users\\Administrator\\PycharmProjects\\cspytest\\pageobject\\loginpage.py\", line 22, in login\n    self.driver.get(ini.url)  # 调用浏览器打开测试地址\n  File \"c:\\users\\administrator\\pycharmprojects\\cspytest\\venv\\lib\\site-packages\\selenium\\webdriver\\remote\\webdriver.py\", line 333, in get\n    self.execute(Command.GET, {'url': url})\n  File \"c:\\users\\administrator\\pycharmprojects\\cspytest\\venv\\lib\\site-packages\\selenium\\webdriver\\remote\\webdriver.py\", line 321, in execute\n    self.error_handler.check_response(response)\n  File \"c:\\users\\administrator\\pycharmprojects\\cspytest\\venv\\lib\\site-packages\\selenium\\webdriver\\remote\\errorhandler.py\", line 242, in check_response\n    raise exception_class(message, screen, stacktrace)\n"}, "steps": [{"name": "登录", "status": "broken", "statusDetails": {"message": "selenium.common.exceptions.NoSuchWindowException: Message: no such window: target window already closed\nfrom unknown error: web view not found\n  (Session info: chrome=86.0.4240.183)\n\n", "trace": "  File \"c:\\users\\administrator\\pycharmprojects\\cspytest\\venv\\lib\\site-packages\\allure_commons\\_allure.py\", line 157, in impl\n    return func(*a, **kw)\n  File \"C:\\Users\\Administrator\\PycharmProjects\\cspytest\\pageobject\\loginpage.py\", line 22, in login\n    self.driver.get(ini.url)  # 调用浏览器打开测试地址\n  File \"c:\\users\\administrator\\pycharmprojects\\cspytest\\venv\\lib\\site-packages\\selenium\\webdriver\\remote\\webdriver.py\", line 333, in get\n    self.execute(Command.GET, {'url': url})\n  File \"c:\\users\\administrator\\pycharmprojects\\cspytest\\venv\\lib\\site-packages\\selenium\\webdriver\\remote\\webdriver.py\", line 321, in execute\n    self.error_handler.check_response(response)\n  File \"c:\\users\\administrator\\pycharmprojects\\cspytest\\venv\\lib\\site-packages\\selenium\\webdriver\\remote\\errorhandler.py\", line 242, in check_response\n    raise exception_class(message, screen, stacktrace)\n"}, "parameters": [{"name": "username", "value": "'hnadmin'"}, {"name": "password", "value": "'1qaz!QAZ'"}, {"name": "verificationCode", "value": "'9527'"}], "start": 1604900006144, "stop": 1604900006146}], "start": 1604900006142, "stop": 1604900006147}, {"name": "login", "status": "broken", "statusDetails": {"message": "selenium.common.exceptions.NoSuchWindowException: Message: no such window: target window already closed\nfrom unknown error: web view not found\n  (Session info: chrome=86.0.4240.183)\n\n", "trace": "  File \"c:\\users\\administrator\\pycharmprojects\\cspytest\\venv\\lib\\site-packages\\pluggy\\callers.py\", line 187, in _multicall\n    res = hook_impl.function(*args)\n  File \"c:\\users\\administrator\\pycharmprojects\\cspytest\\venv\\lib\\site-packages\\_pytest\\fixtures.py\", line 1117, in pytest_fixture_setup\n    result = call_fixture_func(fixturefunc, request, kwargs)\n  File \"c:\\users\\administrator\\pycharmprojects\\cspytest\\venv\\lib\\site-packages\\_pytest\\fixtures.py\", line 924, in call_fixture_func\n    fixture_result = fixturefunc(**kwargs)\n  File \"C:\\Users\\Administrator\\PycharmProjects\\cspytest\\conftest.py\", line 79, in login\n    web.login(ini.username, ini.password, ini.verificationCode)\n  File \"c:\\users\\administrator\\pycharmprojects\\cspytest\\venv\\lib\\site-packages\\allure_commons\\_allure.py\", line 157, in impl\n    return func(*a, **kw)\n  File \"C:\\Users\\Administrator\\PycharmProjects\\cspytest\\pageobject\\loginpage.py\", line 22, in login\n    self.driver.get(ini.url)  # 调用浏览器打开测试地址\n  File \"c:\\users\\administrator\\pycharmprojects\\cspytest\\venv\\lib\\site-packages\\selenium\\webdriver\\remote\\webdriver.py\", line 333, in get\n    self.execute(Command.GET, {'url': url})\n  File \"c:\\users\\administrator\\pycharmprojects\\cspytest\\venv\\lib\\site-packages\\selenium\\webdriver\\remote\\webdriver.py\", line 321, in execute\n    self.error_handler.check_response(response)\n  File \"c:\\users\\administrator\\pycharmprojects\\cspytest\\venv\\lib\\site-packages\\selenium\\webdriver\\remote\\errorhandler.py\", line 242, in check_response\n    raise exception_class(message, screen, stacktrace)\n"}, "steps": [{"name": "登录", "status": "broken", "statusDetails": {"message": "selenium.common.exceptions.NoSuchWindowException: Message: no such window: target window already closed\nfrom unknown error: web view not found\n  (Session info: chrome=86.0.4240.183)\n\n", "trace": "  File \"c:\\users\\administrator\\pycharmprojects\\cspytest\\venv\\lib\\site-packages\\allure_commons\\_allure.py\", line 157, in impl\n    return func(*a, **kw)\n  File \"C:\\Users\\Administrator\\PycharmProjects\\cspytest\\pageobject\\loginpage.py\", line 22, in login\n    self.driver.get(ini.url)  # 调用浏览器打开测试地址\n  File \"c:\\users\\administrator\\pycharmprojects\\cspytest\\venv\\lib\\site-packages\\selenium\\webdriver\\remote\\webdriver.py\", line 333, in get\n    self.execute(Command.GET, {'url': url})\n  File \"c:\\users\\administrator\\pycharmprojects\\cspytest\\venv\\lib\\site-packages\\selenium\\webdriver\\remote\\webdriver.py\", line 321, in execute\n    self.error_handler.check_response(response)\n  File \"c:\\users\\administrator\\pycharmprojects\\cspytest\\venv\\lib\\site-packages\\selenium\\webdriver\\remote\\errorhandler.py\", line 242, in check_response\n    raise exception_class(message, screen, stacktrace)\n"}, "parameters": [{"name": "username", "value": "'hnadmin'"}, {"name": "password", "value": "'1qaz!QAZ'"}, {"name": "verificationCode", "value": "'9527'"}], "start": 1604900006232, "stop": 1604900006234}], "start": 1604900006229, "stop": 1604900006234}, {"name": "login", "status": "broken", "statusDetails": {"message": "selenium.common.exceptions.NoSuchWindowException: Message: no such window: target window already closed\nfrom unknown error: web view not found\n  (Session info: chrome=86.0.4240.183)\n\n", "trace": "  File \"c:\\users\\administrator\\pycharmprojects\\cspytest\\venv\\lib\\site-packages\\pluggy\\callers.py\", line 187, in _multicall\n    res = hook_impl.function(*args)\n  File \"c:\\users\\administrator\\pycharmprojects\\cspytest\\venv\\lib\\site-packages\\_pytest\\fixtures.py\", line 1117, in pytest_fixture_setup\n    result = call_fixture_func(fixturefunc, request, kwargs)\n  File \"c:\\users\\administrator\\pycharmprojects\\cspytest\\venv\\lib\\site-packages\\_pytest\\fixtures.py\", line 924, in call_fixture_func\n    fixture_result = fixturefunc(**kwargs)\n  File \"C:\\Users\\Administrator\\PycharmProjects\\cspytest\\conftest.py\", line 79, in login\n    web.login(ini.username, ini.password, ini.verificationCode)\n  File \"c:\\users\\administrator\\pycharmprojects\\cspytest\\venv\\lib\\site-packages\\allure_commons\\_allure.py\", line 157, in impl\n    return func(*a, **kw)\n  File \"C:\\Users\\Administrator\\PycharmProjects\\cspytest\\pageobject\\loginpage.py\", line 22, in login\n    self.driver.get(ini.url)  # 调用浏览器打开测试地址\n  File \"c:\\users\\administrator\\pycharmprojects\\cspytest\\venv\\lib\\site-packages\\selenium\\webdriver\\remote\\webdriver.py\", line 333, in get\n    self.execute(Command.GET, {'url': url})\n  File \"c:\\users\\administrator\\pycharmprojects\\cspytest\\venv\\lib\\site-packages\\selenium\\webdriver\\remote\\webdriver.py\", line 321, in execute\n    self.error_handler.check_response(response)\n  File \"c:\\users\\administrator\\pycharmprojects\\cspytest\\venv\\lib\\site-packages\\selenium\\webdriver\\remote\\errorhandler.py\", line 242, in check_response\n    raise exception_class(message, screen, stacktrace)\n"}, "steps": [{"name": "登录", "status": "broken", "statusDetails": {"message": "selenium.common.exceptions.NoSuchWindowException: Message: no such window: target window already closed\nfrom unknown error: web view not found\n  (Session info: chrome=86.0.4240.183)\n\n", "trace": "  File \"c:\\users\\administrator\\pycharmprojects\\cspytest\\venv\\lib\\site-packages\\allure_commons\\_allure.py\", line 157, in impl\n    return func(*a, **kw)\n  File \"C:\\Users\\Administrator\\PycharmProjects\\cspytest\\pageobject\\loginpage.py\", line 22, in login\n    self.driver.get(ini.url)  # 调用浏览器打开测试地址\n  File \"c:\\users\\administrator\\pycharmprojects\\cspytest\\venv\\lib\\site-packages\\selenium\\webdriver\\remote\\webdriver.py\", line 333, in get\n    self.execute(Command.GET, {'url': url})\n  File \"c:\\users\\administrator\\pycharmprojects\\cspytest\\venv\\lib\\site-packages\\selenium\\webdriver\\remote\\webdriver.py\", line 321, in execute\n    self.error_handler.check_response(response)\n  File \"c:\\users\\administrator\\pycharmprojects\\cspytest\\venv\\lib\\site-packages\\selenium\\webdriver\\remote\\errorhandler.py\", line 242, in check_response\n    raise exception_class(message, screen, stacktrace)\n"}, "parameters": [{"name": "username", "value": "'hnadmin'"}, {"name": "password", "value": "'1qaz!QAZ'"}, {"name": "verificationCode", "value": "'9527'"}], "start": 1604900006316, "stop": 1604900006318}], "start": 1604900006313, "stop": 1604900006318}, {"name": "login", "status": "broken", "statusDetails": {"message": "selenium.common.exceptions.NoSuchWindowException: Message: no such window: target window already closed\nfrom unknown error: web view not found\n  (Session info: chrome=86.0.4240.183)\n\n", "trace": "  File \"c:\\users\\administrator\\pycharmprojects\\cspytest\\venv\\lib\\site-packages\\pluggy\\callers.py\", line 187, in _multicall\n    res = hook_impl.function(*args)\n  File \"c:\\users\\administrator\\pycharmprojects\\cspytest\\venv\\lib\\site-packages\\_pytest\\fixtures.py\", line 1117, in pytest_fixture_setup\n    result = call_fixture_func(fixturefunc, request, kwargs)\n  File \"c:\\users\\administrator\\pycharmprojects\\cspytest\\venv\\lib\\site-packages\\_pytest\\fixtures.py\", line 924, in call_fixture_func\n    fixture_result = fixturefunc(**kwargs)\n  File \"C:\\Users\\Administrator\\PycharmProjects\\cspytest\\conftest.py\", line 79, in login\n    web.login(ini.username, ini.password, ini.verificationCode)\n  File \"c:\\users\\administrator\\pycharmprojects\\cspytest\\venv\\lib\\site-packages\\allure_commons\\_allure.py\", line 157, in impl\n    return func(*a, **kw)\n  File \"C:\\Users\\Administrator\\PycharmProjects\\cspytest\\pageobject\\loginpage.py\", line 22, in login\n    self.driver.get(ini.url)  # 调用浏览器打开测试地址\n  File \"c:\\users\\administrator\\pycharmprojects\\cspytest\\venv\\lib\\site-packages\\selenium\\webdriver\\remote\\webdriver.py\", line 333, in get\n    self.execute(Command.GET, {'url': url})\n  File \"c:\\users\\administrator\\pycharmprojects\\cspytest\\venv\\lib\\site-packages\\selenium\\webdriver\\remote\\webdriver.py\", line 321, in execute\n    self.error_handler.check_response(response)\n  File \"c:\\users\\administrator\\pycharmprojects\\cspytest\\venv\\lib\\site-packages\\selenium\\webdriver\\remote\\errorhandler.py\", line 242, in check_response\n    raise exception_class(message, screen, stacktrace)\n"}, "steps": [{"name": "登录", "status": "broken", "statusDetails": {"message": "selenium.common.exceptions.NoSuchWindowException: Message: no such window: target window already closed\nfrom unknown error: web view not found\n  (Session info: chrome=86.0.4240.183)\n\n", "trace": "  File \"c:\\users\\administrator\\pycharmprojects\\cspytest\\venv\\lib\\site-packages\\allure_commons\\_allure.py\", line 157, in impl\n    return func(*a, **kw)\n  File \"C:\\Users\\Administrator\\PycharmProjects\\cspytest\\pageobject\\loginpage.py\", line 22, in login\n    self.driver.get(ini.url)  # 调用浏览器打开测试地址\n  File \"c:\\users\\administrator\\pycharmprojects\\cspytest\\venv\\lib\\site-packages\\selenium\\webdriver\\remote\\webdriver.py\", line 333, in get\n    self.execute(Command.GET, {'url': url})\n  File \"c:\\users\\administrator\\pycharmprojects\\cspytest\\venv\\lib\\site-packages\\selenium\\webdriver\\remote\\webdriver.py\", line 321, in execute\n    self.error_handler.check_response(response)\n  File \"c:\\users\\administrator\\pycharmprojects\\cspytest\\venv\\lib\\site-packages\\selenium\\webdriver\\remote\\errorhandler.py\", line 242, in check_response\n    raise exception_class(message, screen, stacktrace)\n"}, "parameters": [{"name": "username", "value": "'hnadmin'"}, {"name": "password", "value": "'1qaz!QAZ'"}, {"name": "verificationCode", "value": "'9527'"}], "start": 1604900006402, "stop": 1604900006405}], "start": 1604900006400, "stop": 1604900006406}, {"name": "login", "status": "broken", "statusDetails": {"message": "selenium.common.exceptions.NoSuchWindowException: Message: no such window: target window already closed\nfrom unknown error: web view not found\n  (Session info: chrome=86.0.4240.183)\n\n", "trace": "  File \"c:\\users\\administrator\\pycharmprojects\\cspytest\\venv\\lib\\site-packages\\pluggy\\callers.py\", line 187, in _multicall\n    res = hook_impl.function(*args)\n  File \"c:\\users\\administrator\\pycharmprojects\\cspytest\\venv\\lib\\site-packages\\_pytest\\fixtures.py\", line 1117, in pytest_fixture_setup\n    result = call_fixture_func(fixturefunc, request, kwargs)\n  File \"c:\\users\\administrator\\pycharmprojects\\cspytest\\venv\\lib\\site-packages\\_pytest\\fixtures.py\", line 924, in call_fixture_func\n    fixture_result = fixturefunc(**kwargs)\n  File \"C:\\Users\\Administrator\\PycharmProjects\\cspytest\\conftest.py\", line 79, in login\n    web.login(ini.username, ini.password, ini.verificationCode)\n  File \"c:\\users\\administrator\\pycharmprojects\\cspytest\\venv\\lib\\site-packages\\allure_commons\\_allure.py\", line 157, in impl\n    return func(*a, **kw)\n  File \"C:\\Users\\Administrator\\PycharmProjects\\cspytest\\pageobject\\loginpage.py\", line 22, in login\n    self.driver.get(ini.url)  # 调用浏览器打开测试地址\n  File \"c:\\users\\administrator\\pycharmprojects\\cspytest\\venv\\lib\\site-packages\\selenium\\webdriver\\remote\\webdriver.py\", line 333, in get\n    self.execute(Command.GET, {'url': url})\n  File \"c:\\users\\administrator\\pycharmprojects\\cspytest\\venv\\lib\\site-packages\\selenium\\webdriver\\remote\\webdriver.py\", line 321, in execute\n    self.error_handler.check_response(response)\n  File \"c:\\users\\administrator\\pycharmprojects\\cspytest\\venv\\lib\\site-packages\\selenium\\webdriver\\remote\\errorhandler.py\", line 242, in check_response\n    raise exception_class(message, screen, stacktrace)\n"}, "steps": [{"name": "登录", "status": "broken", "statusDetails": {"message": "selenium.common.exceptions.NoSuchWindowException: Message: no such window: target window already closed\nfrom unknown error: web view not found\n  (Session info: chrome=86.0.4240.183)\n\n", "trace": "  File \"c:\\users\\administrator\\pycharmprojects\\cspytest\\venv\\lib\\site-packages\\allure_commons\\_allure.py\", line 157, in impl\n    return func(*a, **kw)\n  File \"C:\\Users\\Administrator\\PycharmProjects\\cspytest\\pageobject\\loginpage.py\", line 22, in login\n    self.driver.get(ini.url)  # 调用浏览器打开测试地址\n  File \"c:\\users\\administrator\\pycharmprojects\\cspytest\\venv\\lib\\site-packages\\selenium\\webdriver\\remote\\webdriver.py\", line 333, in get\n    self.execute(Command.GET, {'url': url})\n  File \"c:\\users\\administrator\\pycharmprojects\\cspytest\\venv\\lib\\site-packages\\selenium\\webdriver\\remote\\webdriver.py\", line 321, in execute\n    self.error_handler.check_response(response)\n  File \"c:\\users\\administrator\\pycharmprojects\\cspytest\\venv\\lib\\site-packages\\selenium\\webdriver\\remote\\errorhandler.py\", line 242, in check_response\n    raise exception_class(message, screen, stacktrace)\n"}, "parameters": [{"name": "username", "value": "'hnadmin'"}, {"name": "password", "value": "'1qaz!QAZ'"}, {"name": "verificationCode", "value": "'9527'"}], "start": 1604900006504, "stop": 1604900006506}], "start": 1604900006501, "stop": 1604900006507}, {"name": "login", "status": "broken", "statusDetails": {"message": "selenium.common.exceptions.NoSuchWindowException: Message: no such window: target window already closed\nfrom unknown error: web view not found\n  (Session info: chrome=86.0.4240.183)\n\n", "trace": "  File \"c:\\users\\administrator\\pycharmprojects\\cspytest\\venv\\lib\\site-packages\\pluggy\\callers.py\", line 187, in _multicall\n    res = hook_impl.function(*args)\n  File \"c:\\users\\administrator\\pycharmprojects\\cspytest\\venv\\lib\\site-packages\\_pytest\\fixtures.py\", line 1117, in pytest_fixture_setup\n    result = call_fixture_func(fixturefunc, request, kwargs)\n  File \"c:\\users\\administrator\\pycharmprojects\\cspytest\\venv\\lib\\site-packages\\_pytest\\fixtures.py\", line 924, in call_fixture_func\n    fixture_result = fixturefunc(**kwargs)\n  File \"C:\\Users\\Administrator\\PycharmProjects\\cspytest\\conftest.py\", line 79, in login\n    web.login(ini.username, ini.password, ini.verificationCode)\n  File \"c:\\users\\administrator\\pycharmprojects\\cspytest\\venv\\lib\\site-packages\\allure_commons\\_allure.py\", line 157, in impl\n    return func(*a, **kw)\n  File \"C:\\Users\\Administrator\\PycharmProjects\\cspytest\\pageobject\\loginpage.py\", line 22, in login\n    self.driver.get(ini.url)  # 调用浏览器打开测试地址\n  File \"c:\\users\\administrator\\pycharmprojects\\cspytest\\venv\\lib\\site-packages\\selenium\\webdriver\\remote\\webdriver.py\", line 333, in get\n    self.execute(Command.GET, {'url': url})\n  File \"c:\\users\\administrator\\pycharmprojects\\cspytest\\venv\\lib\\site-packages\\selenium\\webdriver\\remote\\webdriver.py\", line 321, in execute\n    self.error_handler.check_response(response)\n  File \"c:\\users\\administrator\\pycharmprojects\\cspytest\\venv\\lib\\site-packages\\selenium\\webdriver\\remote\\errorhandler.py\", line 242, in check_response\n    raise exception_class(message, screen, stacktrace)\n"}, "steps": [{"name": "登录", "status": "broken", "statusDetails": {"message": "selenium.common.exceptions.NoSuchWindowException: Message: no such window: target window already closed\nfrom unknown error: web view not found\n  (Session info: chrome=86.0.4240.183)\n\n", "trace": "  File \"c:\\users\\administrator\\pycharmprojects\\cspytest\\venv\\lib\\site-packages\\allure_commons\\_allure.py\", line 157, in impl\n    return func(*a, **kw)\n  File \"C:\\Users\\Administrator\\PycharmProjects\\cspytest\\pageobject\\loginpage.py\", line 22, in login\n    self.driver.get(ini.url)  # 调用浏览器打开测试地址\n  File \"c:\\users\\administrator\\pycharmprojects\\cspytest\\venv\\lib\\site-packages\\selenium\\webdriver\\remote\\webdriver.py\", line 333, in get\n    self.execute(Command.GET, {'url': url})\n  File \"c:\\users\\administrator\\pycharmprojects\\cspytest\\venv\\lib\\site-packages\\selenium\\webdriver\\remote\\webdriver.py\", line 321, in execute\n    self.error_handler.check_response(response)\n  File \"c:\\users\\administrator\\pycharmprojects\\cspytest\\venv\\lib\\site-packages\\selenium\\webdriver\\remote\\errorhandler.py\", line 242, in check_response\n    raise exception_class(message, screen, stacktrace)\n"}, "parameters": [{"name": "username", "value": "'hnadmin'"}, {"name": "password", "value": "'1qaz!QAZ'"}, {"name": "verificationCode", "value": "'9527'"}], "start": 1604900006589, "stop": 1604900006592}], "start": 1604900006587, "stop": 1604900006592}], "start": 1604900006587, "stop": 1604900006668}